<mujoco model="bhr8_fc2">
  <compiler angle="radian" meshdir="meshes/"/>

  <option timestep = "0.001" iterations = "50" tolerance = "1e-10" jacobian = "dense" cone = "pyramidal" gravity = "0.0 0.0 -9.81" 
    solver = "Newton" integrator="Euler" impratio = "5.0" />
	
	<size nconmax = "1000" njmax = "1000" nstack = "10000"/>
	
	<visual>
		<map force = "0.025" zfar = "30"/>
		<rgba haze = "0.15 0.25 0.35 1" com = "1.0 0.1 0.1 1"/>
		<quality shadowsize = "2048"/>
		<global offwidth = "800" offheight = "800" fovy = "45" linewidth = "0.1"/>
		<scale forcewidth = "0.05" contactwidth = "0.1" com = "0.2"/>
	</visual>
  <asset>
	  <texture type="skybox" builtin="gradient" rgb1="0.5 0.8 1.0" rgb2="0.4 0.6 0.7" width="512" height="512"/>
	  <texture name="texplane" type="2d" builtin="checker" rgb1=".2 .3 .4" rgb2=".1 0.15 0.2" width="512" height="512" mark="cross" markrgb=".8 .8 .8"/>
	  <texture name="texgeom" type="cube" builtin="flat" mark="cross" width="127" height="1278" rgb1="0.8 0.6 0.4" rgb2="0.8 0.6 0.4" markrgb="1 1 1" random="0.01"/>
	  <material name="matplane" reflectance="0.3" texture="texplane" texrepeat="1 1" rgba = "0.9 0.9 0.9 1" />
	  <material name="matgeom" texture="texgeom" texuniform="true" rgba="0.8 0.6 .4 1"/>	
    <mesh name="rfoot" file="rfoot.stl"/>
    <mesh name="lfoot" file="lfoot.stl"/>
  </asset>

  <worldbody>
	<geom name = "floor" pos = "0 0 0" size = "0 0 .25" type = "plane" material = "matplane" solref = "0.002 0.000001" friction = "3.0 0.5 0.0001" condim = "3"/>

	<light directional = "false" diffuse = ".2 .2 .2" specular = "0 0 0" pos = "0 0 5" dir = "0 0 -1" castshadow = "false"/>
	<light mode = "targetbodycom" target = "torso" directional = "false" diffuse = ".8 .8 .8" specular = "0.3 0.3 0.3" pos = "0 0 4.0" dir = "0 0 -1"/>
    <body name="torso" pos="0 0 1">
      <freejoint name="root"/>
      <inertial pos="-0.01 0 0.303214317947705" quat="1 0 0 0" mass="19.908" diaginertia="0.66 0.62 0.18" />
      <!-- <geom type="mesh" rgba="0.752941 0.752941 0.752941 1" mesh="torso" /> -->
      <site name="imu"  size="0.02" pos="0.0000000 0.00000000 0.0"/>
    <geom size="0.05 0.14 0.28" pos="0 0 0.25" type="box" rgba="0.752941 0.752941 0.752941 1"/>
    <body name="rhip1" pos="0 -0.1 0.02324">
      <inertial pos="-0.078509 0 -0.118031" quat="0.312936 0.634303 0.633788 0.313119" mass="2.38958" diaginertia="0.011987 0.0111943 0.00318774"/>
      <joint name="rhipYaw" pos="0 0 0" axis="0 0 1" range="-3.14 3.14" actuatorfrcrange="-100 100"/>
      <geom size="0.05 0.03" pos="-0.11 0 -0.14" quat="0.707388 0 0.706825 0" type="cylinder" rgba="0.752941 0.752941 0.752941 1"/>
      <body name="rhip2" pos="-0.054 0 -0.13924">
        <inertial pos="0.051206 -0.00273 -0.000288" quat="-0.0508471 0.718896 0.0506336 0.691404" mass="2.50709" diaginertia="0.0040419 0.00361648 0.00344663"/>
        <joint name="rhipRoll" pos="0 0 0" axis="1 0 0" range="-3.14 3.14" actuatorfrcrange="-100 100"/>
        <geom size="0.05 0.04" pos="0.05 0 0" quat="0.707388 0.706825 0 0" type="cylinder" rgba="0.752941 0.752941 0.752941 1"/>
        <body name="rthigh" pos="0.055 -0.0001 0">
          <inertial pos="0.005701 -0.002335 -0.170006" quat="0.999478 -0.00792791 -0.00348956 0.0311153" mass="3.09646" diaginertia="0.0430693 0.0409464 0.00582637"/>
          <joint name="rhipPitch" pos="0 0 0" axis="0 1 0" range="-3.14 3.14" actuatorfrcrange="-100 100"/>
          <geom size="0.05 0.05 0.16" pos="0 0 -0.23" type="box" rgba="0.752941 0.752941 0.752941 1"/>
          <body name="rcalf" pos="0 0 -0.375">
            <inertial pos="0.003761 0 -0.143175" quat="0.99988 -0.000702889 -0.0153326 0.00193635" mass="1.91427" diaginertia="0.0176306 0.017018 0.00210037"/>
            <joint name="rknee" pos="0 0 0" axis="0 1 0" range="-3.14 3.14" actuatorfrcrange="-100 100"/>
            <geom size="0.04 0.04 0.1" pos="0 0 -0.18" type="box" rgba="0.752941 0.752941 0.752941 1"/>
            <body name="rankle" pos="0 0 -0.35">
              <inertial pos="-0.025377 0.000124 0.003585" quat="0.501406 0.49859 0.49859 0.501406" mass="0.139581" diaginertia="0.00117 0.00111002 0.000399977"/>
              <joint name="rankle1" pos="0 0 0" axis="0 1 0" range="-3.14 3.14" actuatorfrcrange="-100 100"/>
              <body name="rfoot" pos="0.031 0 0">
                <inertial pos="-0.016884 0.000166 -0.054343" quat="-0.00139322 0.658253 -0.0050555 0.752779" mass="1.20445" diaginertia="0.00652476 0.00619614 0.0011981"/>
                <joint name="rankle2" pos="0 0 0" axis="1 0 0" range="-3.14 3.14" actuatorfrcrange="-100 100"/>
                <geom type="mesh" rgba="0.752941 0.752941 0.752941 1" mesh="rfoot"/>
              </body>
            </body>
          </body>
        </body>
      </body>
    </body>
    <body name="lhip1" pos="0 0.1 0.02324">
      <inertial pos="-0.078509 0 -0.118031" quat="0.312936 0.634303 0.633788 0.313119" mass="2.38958" diaginertia="0.011987 0.0111943 0.00318774"/>
      <joint name="lhipYaw" pos="0 0 0" axis="0 0 1" range="-3.14 3.14" actuatorfrcrange="-100 100"/>
      <geom size="0.05 0.03" pos="-0.11 0 -0.14" quat="0.707388 0 0.706825 0" type="cylinder" rgba="0.752941 0.752941 0.752941 1"/>
      <body name="lhip2" pos="-0.054 0 -0.13924">
        <inertial pos="0.051206 0.002733 -0.00028" quat="0.0501181 0.718914 -0.051553 0.691371" mass="2.50722" diaginertia="0.00404191 0.00361648 0.00344661"/>
        <joint name="lhipRoll" pos="0 0 0" axis="1 0 0" range="-3.14 3.14" actuatorfrcrange="-100 100"/>
        <geom size="0.05 0.04" pos="0.05 0 0" quat="0.707388 0.706825 0 0" type="cylinder" rgba="0.752941 0.752941 0.752941 1"/>
        <body name="lthigh" pos="0.055 0 0">
          <inertial pos="0.004804 0.002343 -0.169952" quat="0.99957 0.00788906 -0.00488581 -0.0278185" mass="3.09646" diaginertia="0.0430607 0.0408405 0.00572671"/>
          <joint name="lhipPitch" pos="0 0 0" axis="0 1 0" range="-3.14 3.14" actuatorfrcrange="-100 100"/>
          <geom size="0.05 0.05 0.16" pos="0 0 -0.23" type="box" rgba="0.752941 0.752941 0.752941 1"/>
          <body name="lcalf" pos="0 0 -0.375">
            <inertial pos="0.003757 -0.00029 -0.143175" quat="0.999882 0.000728441 -0.0153344 0.000562778" mass="1.91427" diaginertia="0.0176306 0.017019 0.00210036"/>
            <joint name="lknee" pos="0 0 0" axis="0 1 0" range="-3.14 3.14" actuatorfrcrange="-100 100"/>
            <geom size="0.04 0.04 0.1" pos="0 0 -0.18" type="box" rgba="0.752941 0.752941 0.752941 1"/>
            <body name="lankle" pos="0 0 -0.35">
              <inertial pos="-0.025377 0.000124 0.003585" quat="0.513827 0.48578 0.48578 0.513827" mass="0.139581" diaginertia="0.000117 0.000111225 3.97754e-05"/>
              <joint name="lankle1" pos="0 0 0" axis="0 1 0" range="-3.14 3.14" actuatorfrcrange="-100 100"/>
              <body name="lfoot" pos="0.031 0 0">
                <inertial pos="-0.016876 -0.000173 -0.054342" quat="0.0024359 0.658246 0.00581857 0.752776" mass="1.20434" diaginertia="0.00652477 0.00619511 0.00119811"/>
                <joint name="lankle2" pos="0 0 0" axis="1 0 0" range="-3.14 3.14" actuatorfrcrange="-100 100"/>
                <geom type="mesh" rgba="0.752941 0.752941 0.752941 1" mesh="lfoot"/>
              </body>
            </body>
          </body>
        </body>
      </body>
    </body>
    <body name="rshoulder1" pos="-0.02625 -0.13476 0.389">
      <inertial pos="-0.072957 -0.077869 0" quat="0.0679918 0.703732 -0.0683079 0.703898" mass="1.93819" diaginertia="0.007542 0.00713155 0.00236245"/>
      <joint name="rshoulderPitch" pos="0 0 0" axis="0 -1 0" range="-3.14 3.14" actuatorfrcrange="-100 100"/>
      <geom size="0.047 0.035" pos="-0.11 -0.08 0" quat="0.707388 0 0.706825 0" type="cylinder" rgba="0.752941 0.752941 0.752941 1"/>
      <body name="rshoulder2" pos="-0.049 -0.08424 0">
        <inertial pos="0.051 0 -0.017501" quat="0.45725 0.539372 0.539372 0.45725" mass="2.11646" diaginertia="0.003457 0.00313511 0.00264589"/>
        <joint name="rshoulderRoll" pos="0 0 0" axis="1 0 0" range="-3.14 3.14" actuatorfrcrange="-100 100"/>
        <geom size="0.047 0.035" pos="0.05 0 0" type="cylinder" rgba="0.752941 0.752941 0.752941 1"/>
        <body name="rbigarm" pos="0.049 0 -0.05">
          <inertial pos="0.002752 0 -0.123717" quat="0.999552 0 0.0299255 0" mass="1.70306" diaginertia="0.0121441 0.011971 0.00122592"/>
          <joint name="rshoulderYaw" pos="0 0 0" axis="0 0 1" range="-3.14 3.14" actuatorfrcrange="-100 100"/>
          <geom size="0.042 0.1" pos="0 0 -0.15" type="cylinder" rgba="0.752941 0.752941 0.752941 1"/>
          <body name="rforearm" pos="0 -0.01 -0.30324">
            <inertial pos="0.002409 0.01 -0.09" quat="0.707065 -0.00771561 -0.00771561 0.707065" mass="0.181283" diaginertia="0.001374 0.00136863 3.9367e-05"/>
            <joint name="relbow" pos="0 0 0" axis="0 -1 0" range="-3.14 3.14" actuatorfrcrange="-100 100"/>
            <geom size="0.018 0.125" pos="0 0 -0.15" type="cylinder" rgba="0.752941 0.752941 0.752941 1"/>
          </body>
        </body>
      </body>
    </body>
    <body name="lshoulder1" pos="-0.02625 0.13476 0.389">
      <inertial pos="-0.072957 0.077869 0" quat="-0.0683079 0.703898 0.0679918 0.703732" mass="1.93819" diaginertia="0.007542 0.00713155 0.00236245"/>
      <joint name="lshoulderPitch" pos="0 0 0" axis="0 1 0" range="-3.14 3.14" actuatorfrcrange="-100 100"/>
      <geom size="0.047 0.035" pos="-0.11 -0.08 0" quat="0.707388 0 0.706825 0" type="cylinder" rgba="0.752941 0.752941 0.752941 1"/>
      <body name="lshoulder2" pos="-0.049 0.08424 0">
        <inertial pos="0.051 0 -0.017501" quat="0.45725 0.539372 0.539372 0.45725" mass="2.11646" diaginertia="0.003457 0.00313511 0.00264589"/>
        <joint name="lshoulderRoll" pos="0 0 0" axis="1 0 0" range="-3.14 3.14" actuatorfrcrange="-100 100"/>
        <geom size="0.047 0.035" pos="0.05 0 0" type="cylinder" rgba="0.752941 0.752941 0.752941 1"/>
        <body name="lbigarm" pos="0.049 0 -0.05">
          <inertial pos="0.002752 0 -0.123717" quat="0.999552 0 0.0299255 0" mass="1.70306" diaginertia="0.0121441 0.011971 0.00122592"/>
          <joint name="lshoulderYaw" pos="0 0 0" axis="0 0 1" range="-3.14 3.14" actuatorfrcrange="-100 100"/>
          <geom size="0.042 0.1" pos="0 0 -0.15" type="cylinder" rgba="0.752941 0.752941 0.752941 1"/>
          <body name="lforearm" pos="0 0.01 -0.30324">
            <inertial pos="0.0024 -0.01 -0.09" quat="0.707065 -0.00771561 -0.00771561 0.707065" mass="0.181283" diaginertia="0.001374 0.00136863 3.9367e-05"/>
            <joint name="lelbow" pos="0 0 0" axis="0 1 0" range="-3.14 3.14" actuatorfrcrange="-100 100"/>
            <geom size="0.018 0.125" pos="0 0 -0.15" type="cylinder" rgba="0.752941 0.752941 0.752941 1"/>
          </body>
        </body>
      </body>
    </body>
  </body>
  </worldbody>
  <sensor>
		<gyro		       name="root_gyro"	  		  site="imu" />
		<accelerometer name="root_accel"		    site="imu" />
		<framepos 	   name="floatingbasepos"   objtype = "site" 	objname = "imu" />
		<framelinvel   name="floatingbaselinv"  objtype = "site" 	objname = "imu" />
	</sensor>

  <actuator>
    <motor name="rhipYaw" joint="rhipYaw" ctrlrange="-200 200" />
    <motor name="rhipRoll" joint="rhipRoll" ctrlrange="-200 200" />
    <motor name="rhipPitch" joint="rhipPitch" ctrlrange="-200 200" />
    <motor name="rknee" joint="rknee" ctrlrange="-200 200" />
    <motor name="rankle1" joint="rankle1" ctrlrange="-200 200" />
    <motor name="rankle2" joint="rankle2" ctrlrange="-200 200" />
    <motor name="rshoulderPitch" joint="rshoulderPitch" ctrlrange="-200 200" />
    <motor name="rshoulderRoll" joint="rshoulderRoll" ctrlrange="-200 200" />
    <motor name="rshoulderYaw" joint="rshoulderYaw" ctrlrange="-200 200" />
    <motor name="relbow" joint="relbow" ctrlrange="-200 200" /> 
    <motor name="lhipYaw" joint="lhipYaw" ctrlrange="-200 200" />
    <motor name="lhipRoll" joint="lhipRoll" ctrlrange="-200 200" />
    <motor name="lhipPitch" joint="lhipPitch" ctrlrange="-200 200" />
    <motor name="lknee" joint="lknee" ctrlrange="-200 200" />
    <motor name="lankle1" joint="lankle1" ctrlrange="-200 200" />
    <motor name="lankle2" joint="lankle2" ctrlrange="-200 200" />
    <motor name="lshoulderPitch" joint="lshoulderPitch" ctrlrange="-200 200" />
    <motor name="lshoulderRoll" joint="lshoulderRoll" ctrlrange="-200 200" />
    <motor name="lshoulderYaw" joint="lshoulderYaw" ctrlrange="-200 200" />
    <motor name="lelbow" joint="lelbow" ctrlrange="-200 200" />
  </actuator>
</mujoco>
